Workbook

Sheet 상세현황
A1: 요구사항ID * | B1: 요구사항명 * | C1: 요구사항 내용(상세) * | D1: 도출유형 * | E1: 도출단계 * | F1: 요구사항유형 * | G1: 진행상태 | H1: 진행상태 변경사유 | I1: 중요도 * | J1: 난이도 * | K1: 완료예정일 | L1: 적용방안(검토의견) | M1: 업무명 | N1: 기능명 | O1: 세부기능명 | P1: 요구사항 출처구분 | Q1: 요구사항 출처상세 | R1: 요청자 | S1: 요청부서 | T1: 담당자 | U1: 검토자
A2: 관리자가 부여하는 고유 ID | B2: 요구사항 제목 | C2: 요구사항 상세 설명 | D2: 신규/개선/현행/기타 | E2: 분석/설계/구현 | F2: 기능/비기능 | G2: 수용/대체/제외/통합 (기본: 수용) | H2: 대체,제외,통합 선택 시 사유 기재 | I2: 상/중/하 | J2: 상/중/하 | K2: YYYY-MM-DD | L2: 적용방안 또는 검토의견 기재 | M2: 업무 구분 | N2: 기능 구분 | O2: 세부 기능 구분 | P2: 제안요청/기술협상/회의/기타 | Q2: 출처에 대한 상세 설명 | R2: 발주기관 요청자 | S2: 발주기관 요청부서 | T2: 사업자 담당자 | U2: 사업자 검토자
A3: RQ-FUN-자체조달-100-1000 | B3: 다국어지원(영어) | C3: 영어지원 범위내의 화면에 대한 영문 지원 (코이카) | D3: 신규 | E3: 설계 | F3: 비기능 | G3: 수용 | I3: 중 | J3: 중 | K3: 2022-12-06 | M3: 사업관리/품질 | N3: 다국어 | O3: 다국어 | Q3: 자체조달기관 인터뷰 | T3: 이동헌 | U3: 이동헌 | V3: 1. 검토결과 - 대상화면 선정 협의 및 대상화면 확정 - 대상화면 영문 적용 확인 2. 구현방안/제약사항 - (코이카) 기관 협의 및 개발 적용 진행 확인 | AA3: 0 | AB3: 0 | AC3: 0 | AD3: 0
A4: RQ-FUN-보안기능-012-0020 | B4: 내부자료 인터넷망 유출 대비 검증체계 구축 | C4: ㅇ내부망에서 게시판 글쓰기 등을 통해 파일 첨부 시 사전 혹은 사후 결재 프로세스를 구축하고, 결재권자들에게 주기적으로 알림 ㅇ내부망에서 작성되어 외부로 공개될 수 있는 모든 온라인 창구에는 창구식별번호를 부여하고, 이력 관리 시 창구식별번호, 글제목, 첨부파일명, 작성자ID, IP주소, 작성일시 등을 기록하여 추적가능성 보장 ㅇ결재권자는 내부망에서 작성되어 외부망에 게시된 첨부파일 내용 확인이 가능해야 함 ㅇ일반직원 대상 결재권자는 부서장, 용역직원 대상 결재권자는 사업담당공무원으로 지정. 단, 조달청을 제외한 타수요기관은 대표 결재권자 지정 등을 통해 내부망 자료유출 추적이 가능하도록 서비스 제공 ㅇ프로그램 DB계정에서는 이력테이블에 자료 입력만, 결재권자 DB계정에서는 이력테이블 조회 및 결재가 가능하도록 DB계정을 분리 | D4: 현행 | E4: 분석 | F4: 비기능 | G4: 수용 | I4: 중 | J4: 중 | K4: 2021-11-30 | M4: 사업관리/품질 | N4: 보안 | O4: 안전입찰 프로그램 제거 | Q4: FUN-보안기능-012 | T4: 이동헌 | U4: 이동헌 | V4: [검토결과] 내부망 작성 -> 외부망 공개(모든 온라인창구/예:게시판 글쓰기) 화면에 대한 관리체계 구축 [구현방안/제약사항] 1. 운영관리(FUN-운영관리-003/서비스운영관리-통합게시판생성관리) 등과 연관, 타 화면도 분석 필요 | Y4: 김훈희 | Z4: 이요한 | AA4: 0 | AB4: 0 | AC4: 0 | AD4: 0
A5: RQ-FUN-보안기능-015-0010 | B5: 비대면 대리인 등록절차의 외부기관 자문 | C5: ㅇ비대면 대리인 등록 절차 설계 후 외부 기관의 자문을 받아 그 결과에 대하여 보완해야 함 | D5: 현행 | E5: 분석 | F5: 비기능 | G5: 수용 | I5: 중 | J5: 중 | K5: 2021-11-30 | M5: 사업관리/품질 | N5: 보안 | O5: 비대면 대리인 등록 절차 대외 인증 | Q5: FUN-보안기능-015 | T5: 이동헌 | U5: 이동헌 | V5: 1. 검토결과 - 비대면 대리인 등록절차의 외부기관 자문을 받는 방안 2. 구현방안/제약사항 - 응용팀 : 비대면 등록절차 관련 설계 문서 ( 5월말 ) - 사업관리 : 외부 자문 계획서 및 결과서 (6월초) | Y5: 김훈희 | Z5: 이요한 | AA5: 0 | AB5: 0 | AC5: 0 | AD5: 0
A6: RQ-SER-001-0010 | B6: 정보보호 법규 준수 | C6: - 제안사는 용역수행기간 중 “국가정보보안 기본지침, 조달청 정보보안업무규정” 등 정보보호 관련 법규를 준수하며, 대외보안유지에 적극 협조하여야 함 - 사업 수행과정에서 취득한 자료와 정보에 관하여 사업수행 중일 때는 물론 사업완료 후에도 이를 외부에 유출해서는 안되며, 사업종료 시에는 완전 폐기 또는 반납해야 함 | D6: 현행 | E6: 분석 | F6: 비기능 | G6: 수용 | I6: 상 | J6: 중 | K6: 2021-11-30 | M6: 사업관리/품질 | N6: 보안 | O6: 정보보호 | Q6: SER-001 | T6: 조황근 | U6: 이동헌 | V6: 1. 검토결과 - 정보보호관련 법규 준수 및 이행(정보보호관리계획 준수) 2. 구현방안/제약사항 - 조달청 보안업무 시행세칙 준수 - 보안관리계획서 - 사업수행과정에서 취득한 자료와 정보에 대하여 외부 유출 금지 및 사업종료 시 완전 폐기함 | AA6: 0 | AB6: 0 | AC6: 0 | AD6: 0
A7: RQ-SER-001-0030 | B7: 보안적용가이드 기준 점검 | C7: 보안적용가이드를 통하여 사업 추진 및 보안적용가이드의 체크리스트를 통하여 사업 추진 결과물에 대하여 점검하여 제출하여야 함 | D7: 현행 | E7: 분석 | F7: 비기능 | G7: 수용 | I7: 상 | J7: 중 | K7: 2021-11-30 | M7: 사업관리/품질 | N7: 보안 | O7: 정보보호 | Q7: SER-001 | T7: 이동헌 | U7: 이동헌 | V7: 1. 검토결과 - 사업추진 결과물에 대하여 보안적용가이드의 체크리스트를 통한 점검 후 제출 2. 구현방안/제약사항 - 정보보안체크리스트(사전단계, 분석단계) 기반 검토 - 각 영역 적용여부 보안점검 진행 - 분석단계말 체크리스트(RFP-별표5,6) 기반 진행 | AA7: 0 | AB7: 0 | AC7: 0 | AD7: 0
A8: RQ-SER-001-0040 | B8: 보안대책 반영 시스템 개발 | C8: ㅇ보안 점검 등 보안 요구사항 반영 - 용역 사업수행계획서 작성 시 적정한 보안대책을 수립하여야 하며, 이 보안대책을 반영하여 시스템을 개발하여야 함 - 시스템 분석‧설계 및 구축, 사업수행 전 단계에 걸쳐 보안성 검토를 받아 보안대책의 적정성을 확인하여야 함 | D8: 현행 | E8: 분석 | F8: 비기능 | G8: 수용 | I8: 상 | J8: 중 | K8: 2021-11-30 | M8: 사업관리/품질 | N8: 보안 | O8: 정보보호 | Q8: SER-001 | T8: 이동헌 | U8: 이동헌 | V8: 1. 검토결과 - 개발 시 보안대책 반영 2. 구현방안/제약사항 - 시큐어코딩가이드수립 및 교육수행, 시스템개발 - Code Inspection(소나큐브) 개발 점검 수행 - 공통기술:표준가이드 문서작성, 교육수행 - 설계/개발단계 시큐어코딩 점검 수행(전문가) - 웹취약점(모의해킹) 전문업체 수행 | AA8: 0 | AB8: 0 | AC8: 0 | AD8: 0
A9: RQ-SER-001-0050 | B9: 개인정보보호 법령 준수 | C9: ㅇ개인정보보호 법령 등 관련 규정에 따라 개인정보 관련 업무를 처리해야 함 - 개인정보보호법 등 개인정보보호 관련 법규, 지침의 준수와 더불어, 이에 따른 개인정보처리위탁에 관한 협약사항을 이행하여야 함 | D9: 현행 | E9: 분석 | F9: 비기능 | G9: 수용 | I9: 상 | J9: 중 | K9: 2021-11-30 | M9: 사업관리/품질 | N9: 보안 | O9: 정보보호 | Q9: SER-001 | T9: 왕희집 | U9: 이동헌 | V9: 1. 검토결과 - 개인정보보호 법령 등 관른 규정에 따른 업무 처리 방안 2. 구축방안/제약사항 - 개인정보영향평가수행 결과 개선 및 보완 - 응용업무 반영 수행 | AA9: 0 | AB9: 0 | AC9: 0 | AD9: 0
A10: RQ-SER-002-0010 | B10: 개인정보 보호 | C10: ㅇ전 업무 수행 목적 및 범위 외 개인정보의 처리를 금함 ㅇ개인정보의 제3자 제공 및 재위탁을 금함 ㅇ위탁받은 업무와 관련하여 개인정보를 처리하는 과정에서 개인정보보호법 및 제안업체가 준수해야 할 의무를 위반하여 발생하는 손해배상에 대한 전적인 책임을 짐 ㅇ위탁받은 개인정보가 분실ㆍ도난ㆍ유출ㆍ변조 또는 훼손되지 아니하도록 주의하여야하며, 조달청이 개인정보 처리실태를 위해 실시하는 감독 및 점검에 응해야 함 ㅇ개발 및 테스트 시 개인정보가 포함된 테스트 데이터의 경우 실 데이터가 아닌 가상의 개인정보(가상 성명/주민번호/주소 등)를 생성하여 활용하여야 함 | D10: 현행 | E10: 분석 | F10: 비기능 | G10: 수용 | I10: 상 | J10: 중 | K10: 2021-11-30 | M10: 사업관리/품질 | N10: 보안 | O10: 개인정보 | Q10: SER-002 | T10: 조황근 | U10: 이동헌 | V10: 1. 검토결과 - 개인정보보호 관련 조달청 요청사항 준수하여 사업 수행 2. 구현방안/제약사항 - 개인정보위탁처리동의서 제출(컨소대표) - 보안관리계획서에 목차 추가하여 관리(개인정보관리) - 테스트데이터 생성할때 개인식별정보를 가상정보로 생성 | AA10: 0 | AB10: 0 | AC10: 0 | AD10: 0
A11: RQ-SER-003-0010 | B11: 개인정보처리 위탁 준수사항 | C11: ㅇ용역사업자는 개인정보처리위탁 준수사항 및 개인정보보호법 등 관련 규정에 따라 개인정보 관련 업무를 처리해야 함 ㅇ제안사는 개인정보보호 책임자를 지정하고, 개인정보보호를 위해 관계법령에서 정한 관리적ㆍ기술적 조치 사항과 사업 참여자교육 등을 포함하여 개인정보보호계획을 수립하여 제출하여야 함 - 접근 권한의 제한 및 관리 조치 - 접근 권한을 확인하기 위한 식별 및 인증 조치 - 권한 없는 접근을 차단하기 위한 시스템의 설치 등 조치 - 안전하게 저장ㆍ전송될 수 있도록 하기 위한 암호화 등 조치 - 접속기록의 보관 및 위ㆍ변조 방지를 위한 조치 - 보안 프로그램의 설치 및 주기적인 갱신ㆍ점검 조치 - 안전한 보관을 위한 출입통제ㆍ잠금장치 등 물리적 조치 ㅇ제안사는 개인정보보호 유출이 발생될 경우에는 인지 즉시 발주기관과 해당기관에 통지하고, 피해 최소화를 위한 대책을 마련하고 필요한 조치를 하여야 함 - 개인정보의 유출확산방지를 위해 접속경로 차단 등 긴급한 대응은 즉시 취하여야 함 | D11: 현행 | E11: 분석 | F11: 비기능 | G11: 수용 | I11: 상 | J11: 중 | K11: 2021-11-30 | M11: 사업관리/품질 | N11: 보안 | O11: 개인정보 | Q11: SER-003 | T11: 조황근 | U11: 이동헌 | V11: 1. 검토결과 - 개인정보처리위탁 준수사항 및 개인정보보호법 등 관련 규정에 따라 개인정보 관련 업무 처리 2. 구현방안/제약사항 - 보안관리계획서에 목차 추가하여 관리(개인정보관리) - 테스트데이터할때 개인식별정보 가상정보생성 | AA11: 0 | AB11: 0 | AC11: 0 | AD11: 0
A12: RQ-SER-003-0020 | B12: 개인정보보호 교육 | C12: 제안사는 참여인력에 대하여 개인정보보호 교육을 실시하고 결과를 제출하여야 함 | D12: 현행 | E12: 분석 | F12: 비기능 | G12: 수용 | I12: 상 | J12: 중 | K12: 2021-11-30 | M12: 사업관리/품질 | N12: 보안 | O12: 개인정보 | Q12: SER-003 | T12: 조황근 | U12: 이동헌 | V12: 1. 검토결과 - 참여인력 개인정보보호교육 실시 2. 구현방안/제약사항 - 보안교육 내용에 개인정보 보안 포함 - 신규투입인력 교육 시 개인정보보안 교육 실시 및 결과 제출 | AA12: 0 | AB12: 0 | AC12: 0 | AD12: 0
A13: RQ-SER-004-0010 | B13: 시큐어코딩 가이드 준수 | C13: ㅇ시큐어코딩 등 가이드 준수 및 보안 안전성을 고려하여 분석‧설계 단계부터 응용프로그램 개발 추진하여야 함 - 「소프트웨어 개발보안가이드」준수한 시스템 개발 - 정보보호 관리 체계 및 보안 요건 적용 - 보안 취약점 등 프로그램 개발 시 보안 요건 준수 하여 추진하되, 정보호호관리체계 및 보안 적용 가이드 등을 통하여 상세 요건을 도출한 뒤 반영햐여야 함 | D13: 현행 | E13: 분석 | F13: 비기능 | G13: 수용 | I13: 상 | J13: 상 | K13: 2023-04-30 | M13: 사업관리/품질 | N13: 보안 | O13: 시스템구축 보안 | Q13: SER-004 | T13: 김야중 | U13: 김야중 | V13: 1. 검토결과 1) 분석 설계 단계에서 소프트웨어 개발 보안 가이드 준수할 수 있도록 가이드를 작성하고 , 개발 단계 교육/가이드 수행하고 점검함으로 가이드를 준수한 시스템 개발 2) 정보호호관리체계 및 보안 적용 가이드 등을 통하여 프로그램 개발 2. 구현방안/제약사항 [결과] 시큐어코딩가이드, 시큐어코딩점검결과서, 모의해킹점검결과서 | W13: 시큐어코딩 | Y13: 김훈희 | Z13: 이요한 | AA13: 0 | AB13: 0 | AC13: 0 | AD13: 0
A14: RQ-SER-005-0020 | B14: 외부점검 대응 | C14: ㅇ웹호환성‧접근성‧개방성 등 관련 지침 준수 및 내･외부점검 대응 - 전자정부 웹호환성·접근성·개방성 준수지침에 따른 시스템 분석, 설계 및 개발 ㅇ외부 취약점 및 보안 점검 결과에 따른 시스템 개선하여야 함 | D14: 현행 | E14: 분석 | F14: 비기능 | G14: 수용 | I14: 상 | J14: 상 | K14: 2021-11-30 | M14: 사업관리/품질 | N14: 보안 | O14: 소프트웨어 보안 | Q14: SER-005 | T14: 이동헌 | U14: 이동헌 | V14: 1. 검토결과 - 웹호환성, 접근성, 개발성 등 관련 지침 준수 2. 구현방안/제약사항 - 웹접근성 점검 전문가 투입 - 보안취약점 점검 전문가 투입 | W14: 시스템보안 | Y14: 김훈희 | Z14: 이요한 | AA14: 0 | AB14: 0 | AC14: 0 | AD14: 0
A15: RQ-SER-006-0010 | B15: 수행인력 보안서류 | C15: ㅇ계약상대자는 정보유출을 방지하기 위하여 과업참여자는 아래 서류를 제출 해야 함 (1) 재직증명서 (2) 보안서약서 (3) 보안확약서 (4) 청렴서약서 ㅇ용역사업 참여인원은 보안서약서(하도급 업체까지 포함하여 각사 대표자 명의 보안서약서 포함)에 자필서명 후, 발주기관에 제출 해야 함 - 하도급 계약 체결 시 본사업 비밀유지 조항 포함 하여야 함 | D15: 현행 | E15: 분석 | F15: 비기능 | G15: 수용 | I15: 상 | J15: 하 | K15: 2021-11-30 | M15: 사업관리/품질 | N15: 보안 | O15: 인적보안 | Q15: SER-006 | T15: 조황근 | U15: 이동헌 | V15: 1. 검토결과 - 정보유출 방지를 위한 서류 제출 2. 구현방안/제약사항 - 수행인력 보안서약서 제출(시스템) - 청렴서약서(대표자 제출/착수계), 업체대표 보안서약서(시스템) * 재직증명서는 필요 시 제출 | AA15: 0 | AB15: 0 | AC15: 0 | AD15: 0
A16: RQ-SER-006-0020 | B16: 보안책임관 및 보안담당 역할 | C16: ㅇ용역사업 참여인원 중 최고직급자를 보안책임관으로 지정하여 발주기관의 승인을 받아야 함 ㅇ보안책임관 및 보안담당자의 직무‧역할 - 보안사항의 도난, 분실 등을 방지에 대한 제반 보안사항의 조치, 보안책임관을 지정‧운영 - 보안상 중요하다고 생각되는 모든 기록과 자료는 잠금장치가 되어있는 곳에 보관하고, 보안담당자는 이를 관리해야함 - 보안에 관한 심사 및 검증을 필요로 하는 경우 사전에 발주기관의 보안관련 담당자에게서 필요한 조치를 받아야 함 - 발주기관의 서면에 의한 승낙 없이 본 계약에 관련하여 알게 된업무상 기밀은 과업기간중은 물론 본 계약 종료 후에도 제3자에게 누설 금지 | D16: 현행 | E16: 분석 | F16: 비기능 | G16: 수용 | I16: 상 | J16: 하 | K16: 2021-11-30 | M16: 사업관리/품질 | N16: 보안 | O16: 인적보안 | Q16: SER-006 | T16: 조황근 | U16: 이동헌 | V16: 1. 검토결과 - 보안책임관/보안담당자 지정 및 역할 정의 2. 구현방안/제약사항 - 보안책임관으로 총괄PM 지정 - 보안관리계획에 직무 및 역할 정의 - 보안상 중요 자료에 대한 물리적 보안 조치 | AA16: 0 | AB16: 0 | AC16: 0 | AD16: 0
A17: RQ-SER-006-0030 | B17: 정보보안교육 수행 | C17: 참여인원에 대하여 월1회 정보보안교육을 수행하고, 교육결과에 대하여 발주기관의 확인을 받아야 함 | D17: 현행 | E17: 분석 | F17: 비기능 | G17: 수용 | I17: 상 | J17: 하 | K17: 2021-11-30 | M17: 사업관리/품질 | N17: 보안 | O17: 인적보안 | Q17: SER-006 | T17: 조황근 | U17: 이동헌 | V17: 1. 검토결과 - 참여인원 보안교육 실시 2. 구현방안/제약사항 - 신규 투입 시 보안교육 실시 - 월 1회 보안교육 실시 | AA17: 0 | AB17: 0 | AC17: 0 | AD17: 0
A18: RQ-SER-006-0040 | B18: 문서자료 보안 | C18: 정보화 사업 추진관련 각종 문서자료(공문, 책자, 출력물 등)의 보안 및 자료 관리를 해야 함 | D18: 현행 | E18: 분석 | F18: 비기능 | G18: 수용 | I18: 상 | J18: 하 | K18: 2021-11-30 | M18: 사업관리/품질 | N18: 보안 | O18: 인적보안 | Q18: SER-006 | T18: 조황근 | U18: 이동헌 | V18: 1. 검토결과 - 사업 추진고정에서 취득/생성 된 자료에 대한 관리 2. 구현방안/제약사항 - 보안관리계획서에 문서보안 계획 수립 - 사업과정에서 취득/생성 한 자료 관리 수행 | AA18: 0 | AB18: 0 | AC18: 0 | AD18: 0
A19: RQ-SER-006-0050 | B19: 개인정보 보안 | C19: 개인정보 관련 법제도에 의거 안전성 확보에 필요한 조치(기술적,관리적 조치)를 하여야 함 | D19: 현행 | E19: 분석 | F19: 비기능 | G19: 수용 | I19: 상 | J19: 하 | K19: 2021-11-30 | M19: 사업관리/품질 | N19: 보안 | O19: 인적보안 | Q19: SER-006 | T19: 왕희집 | U19: 이동헌 | V19: 1. 검토결과 - 개인정보 관련 법제도에 의거 안전성 확보에 필요한 조치 방안 2. 구축방안/제약사항 - 개인정보 영향평가 수행 및 결과 조치 - 개인정보 안정성 확인 및 조치 | AA19: 0 | AB19: 0 | AC19: 0 | AD19: 0
A20: RQ-SER-006-0060 | B20: 참여인력(인력교체) 보안 | C20: ㅇ용역사업 참여인원은 용역업체 임의로 교체할 수 없으며, 신상변동(해외여행 포함) 사항 발생 시 발주기관에 즉시 보고하여야 함 ㅇ사업 수행 인력 교체 시 PC포맷 등 사업 관련 자료의 외부유출을 방지를 위해 적절한 조치 수행하여야 함 | D20: 현행 | E20: 분석 | F20: 비기능 | G20: 수용 | I20: 상 | J20: 하 | K20: 2021-11-30 | M20: 사업관리/품질 | N20: 보안 | O20: 인적보안 | Q20: SER-006 | T20: 조황근 | U20: 이동헌 | V20: 1. 검토결과 - 투입 인력/장비 관리 수행 2. 구현방안/제약사항 - 신규인력 투입 및 철수/교체 시 절차에 따라 등록 및 승인 요청 - 반입장비에 대하여 보안프로그램 설치 및 포트Locker, 보안스티거 등 보안관리(정보보호포털) - 철수 시 장비 포맷 등 절차에 따라 처리(정보보호포털) | AA20: 0 | AB20: 0 | AC20: 0 | AD20: 0
A21: RQ-SER-007-0010 | B21: 사업장 보안관리 | C21: ㅇ계약당사자는 사업수행을 위하여 필요한 장소 및 설비, 기타 작업환경(작업장소 등)을 발주기관과 협의하여 정함 - 작업장소 상호 협의 시, 제안요청서 내 명시된 보안요구사항을 준수한 작업장소를 제시할 수 있으며, 이때 보안사고 등 위험요인을 식별하여 이에 대한 대응방안 및 제안요청서에 명시한 보안요구사항 등을 준수하여 원격지 개발 등에 따른 구체적인 보안관리 대책을 제시하여야 함 - 발주기관에서는 제시된 작업장소에 관하여 우선 검토하며, 공급자가 제시한 작업장소가 보안요구사항을 준수하지 못한 경우 거부할 수 있음 ㅇ사업수행 사무실은 원칙적으로 실제 사업에 참여하는 자만 출입을 허용하고, 비인가자 출입관리 대장을 비치하여 관리함 ㅇ사업 내에서 문서나 프로그램 버전 및 처리지침 등은 관리적 보안과 함께 잠금장치, 통제구역 등을 통하여 물리적 보안 실시함 ㅇ사업장에 대하여 일일보안점검 및 월1회 보안점검을 실시하여야 하고, 실적 보고, 보안관리대장을 비치 운영하고 발주기관의 확인을 받아야 함 ㅇ잠금장치 등 사업장에 대한 물리적 보안 조치 및 DRM 구비 - 용역사업 수행 장소에서 비인가 무선 AP설정 금지 및 사용 통제실시 ㅇ투입인력이 상주 근무하는 사업장에 대하여 화재 및 도난 사고 등에 따른 대비책 마련 ㅇ사업장의 네트워크는 내부망으로 구성하고 외부망 접근 차단 ㅇ내ㆍ외부망 접근에 대한 보안 관리 - 발주기관 내부망에 대한 접속은 반드시 발주기관의 승인을 득한 후 사용하여야 함 - 사업장은 업무망과 인터넷망을 분리하고, PC는 업무망과 인터넷망을 혼용해서는 안 됨 ㅇ기타 사업장 및 장비 보안과 관련하여 발주기관의 지침에 따름 | D21: 현행 | E21: 분석 | F21: 비기능 | G21: 수용 | I21: 상 | J21: 하 | K21: 2021-11-30 | M21: 사업관리/품질 | N21: 보안 | O21: 물리적보안 | Q21: SER-007 | T21: 조황근 | U21: 이동헌 | V21: 1. 검토결과 - 사업장에 대한 물리적 보안관리 수행 2. 구현방안/제약사항 - 조달청의 지침에 따라 사업장의 물리적 보안 관리 실시 - 비인가자 출입통제 및 출입관리대장 작성 - 일일 및 월1회 보안점검 실시 - 내부망과 인터넷망을 분리하고 조달청의 승인을 득하여 사용 | AA21: 0 | AB21: 0 | AC21: 0 | AD21: 0
A22: RQ-SER-007-0020 | B22: 사업장 장비 보안관리 | C22: ㅇ정보화 사업수행 시 필요한 각종 장비(주전산기, 통신장비, 데이터베이스, 응용프로그램, PC 등)에 대한 보안 관리 - 사업장의 정보시스템에 바이러스 백신 정품 SW를 설치하고, 자동 업데이트, 실시간 점검을 수행하는지 수시로 점검해야 함 - 사업 CD-RW, USB 등의 보조매체 기록 장치는 발주기관과의 상호 협의하여 제한된 PC에서만 사용해야 함 - 사업장내 보조기억장치(외장형 HDD, USB 등) 반입ㆍ반출 불가함. 다만, 산출물 작성 등의 보조기억매체가 필요한 경우 발주기관의 관리 하에 사용하도록 함 - 용역사업 종료 시까지는 반입된 PC의 반출 금지. 다만, 사업 수행 상 외부 반출이 필요한 경우는 자료 유출에 대비한 보안대책을 발주기관에 제출하여 발주기관 보안관리 담당자 승인 후 최소한의 장비만 반출 할 수 있음 ㅇ사업참여인원의 비인가 휴대용 저장매체(USB, CD/DVD, 스마트폰, 태블릿 PC, MP3 등)가 사업장내 정보시스템에 연결되는 것을 기술적으로 차단하고, 월1회 정상동작 여부를 점검ㆍ조치하여야 함 ㅇ정보시스템(휴대용 저장매체 포함)을 외부에 반출ㆍ입하는 경우, 반입시에는 악성코드 감염여부를, 반출 시에는 자료무단 반출여부를 확인하고 정보시스템 반ㆍ출입 대장에 기록하여야 함 ㅇ사업장에서 사용하는 모든 정보시스템에 대하여 관리자를 지정하여 장비별로 장비현황라벨을 부착 및 정보시스템 관리대장을 작성하고 변경사항에 대해 현행화하여야 함 ㅇ사업장 PC에 대하여 월1회 보안점검도구 수행 및 결과를 관리해야함 ㅇ사업장의 정보시스템에 바이러스 백신 정품 SW를 설치하고, 자동 업데이트, 실시간 점검을 수행하는 지 수시로 점검하여야 함 ㅇ사업에 참여한 사업자가 활용한 PC 및 서버의 경우, 사업 완료 후 최종 산출물을 발주기관에 제출하고, 자료의 복구가 불가능하도록 조치함 ㅇ장애, 사고 등으로 인한 시스템 피해에 대비해 최근에 백업한 시점의 내용으로 복구할 수 있는 백업정책을 수립하고 실행함 | D22: 현행 | E22: 분석 | F22: 비기능 | G22: 수용 | I22: 상 | J22: 하 | K22: 2021-11-30 | M22: 사업관리/품질 | N22: 보안 | O22: 물리적보안 | Q22: SER-007 | T22: 조황근 | U22: 이동헌 | V22: 1. 검토결과 - 사업수행 시 필요한 장비에 대한 보안관리 수행 2. 구현방안/제약사항 - 조달청 절차에 따라 장비 반입 및 철수 처리 - 반입장비에 피수 보안프로그램 설치 - 반입장비에 대하여 장비관리대장 기록 및 라벨 부착 - 월1회 보안점검도구 수행 및 관리 | AA22: 0 | AB22: 0 | AC22: 0 | AD22: 0
A23: RQ-SER-008-0010 | B23: 자료 및 산출물 보안관리 | C23: ㅇ사업수행으로 생산되는 산출물 및 기록은 보안책임관이 인가하지 않은 자에게 제공ㆍ대여ㆍ열람을 금지함 ㅇ사업관련 자료 및 사업과정에서 생산된 산출물은 보안책임관이 지정한 PC 등(반드시 인터넷과 분리)에 저장ㆍ관리하여야 함 ㅇ제안요청서 등에 명시한 누출금지 대상정보를 사용할 경우 자료관리 대장을 작성하여 인계ㆍ인수자가 직접 서명한 후 사용하고 사업완료시 관련 자료는 반납하여야 함 ㅇ비밀문서(대외비 포함)는 매일 퇴근 시 반납하여야 하며, 비밀문서를 제외한 일반문서는 제공된 사무실에 잠금장치가 된 보관함이 있을 경우 보관함에 보관하여야 함 ㅇ사업관련 자료는 인터넷 웹하드ㆍP2P 등 인터넷 자료공유사이트 및 개인메일함 저장을 금지하고 발주기관과 사업수행업체간 자료전송이 필요한 경우는 발주기관과 협의한 방법을 이용하여 송ㆍ수신하고 주기적으로 삭제 관리하여야 함 ㅇ사업완료 후 생산된 최종산출물은 인수‧인계서를 통하여 발주기관에 반납하고, PC 완전삭제 등 보안조치를 통해 사업관련 산출물(중간산출물 포함)을 모두 삭제하여야 함. ㅇ본 과업에 따른 중간 및 최종 성과물에 대해서 사업자는 발주기관의 승인 없이 외부에 제공 또는 공포 할 수 없음 | D23: 현행 | E23: 분석 | F23: 비기능 | G23: 수용 | I23: 상 | J23: 하 | K23: 2021-11-30 | M23: 사업관리/품질 | N23: 보안 | O23: 문서보안 | Q23: SER-008 | T23: 조황근 | U23: 이동헌 | V23: 1. 검토결과 - 사업수행 시 취득/생성한 산출물 관리 2. 구현방안/제약사항 - 사업수행 시 취득한 산출물에 대한 보안관리 - 보안책임자 지정 - 취득한 출력산출물에 대한 자료 인수인계대장 작성 - 디지털 자료는 다운로드시 다운로드 로그 이력관리(정보보호포털) - 생성한 산출물은 산출물서버에 관리 | AA23: 0 | AB23: 0 | AC23: 0 | AD23: 0
A24: RQ-SER-016-0010 | B24: 모의해킹 / 취약점 조치 | C24: ㅇ제3자 화이트해커 모의해킹 수행 결과 미흡한 사항을 조치해야 함 ㅇ모의해킹 결과 별도 예산이 수반될 것으로 예상되는 항목에 대하여 사업계획서 소요예산 산출내역서에 반영하여야 함 ㅇ모의해킹 결과 예산이 수반되는 항목의 내용이 사업계획서에 반영되지 않는 항목이 있는 경우 발주기관은 중장기적인 조치방안을 강구하여야 함 | D24: 현행 | E24: 분석 | F24: 비기능 | G24: 수용 | I24: 상 | J24: 상 | K24: 2021-11-30 | M24: 사업관리/품질 | N24: 보안 | O24: 기술보안 | Q24: SER-016 | T24: 왕희집 | U24: 이동헌 | V24: 1. 검토결과 - 모의해킹 수행결과 조치방안 2. 구축방안/제약사항 - 모의해킹 전문인력 투입 - 모의해킹 수행 결과 조치사항 반영 | AA24: 0 | AB24: 0 | AC24: 0 | AD24: 0
A25: RQ-SER-017-0010 | B25: 개인정보영향평가 / 대책수립 | C25: ㅇ개인정보보호법 제33조 및 동법 시행령 제35조에 따른 개인정보영향평가를 받아야 함 ㅇ개인정보영향평가 기관이 ‘개인정보 영향평가 수행안내서(행안부 매뉴얼)’, ‘개인정보 위험도 분석기준 및 해설서(행안부 공고)’를 근간으로 평가한 개인정보영향평가 결과에 대해서는 주사업자가 개발시 반영해야 함 ㅇ개인정보영향평가 결과 별도 예산이 수반될 것으로 예상되는 항목에 대하여 사업계획서 소요예산 산출내역서에 반영하여야 함 ㅇ개인정보영향평가 결과 예산이 수반되는 항목의 내용이 사업계획서에 반영되지 않는 항목이 있는 경우 발주기관은 중장기적인 조치방안을 강구하여야 함 | D25: 현행 | E25: 분석 | F25: 비기능 | G25: 수용 | I25: 상 | J25: 중 | K25: 2021-11-30 | M25: 사업관리/품질 | N25: 보안 | O25: 기술보안 | Q25: SER-017 | T25: 왕희집 | U25: 이동헌 | V25: 1. 검토결과 - 개인정보 영향평가 수행 2. 구축방안/제약사항 - 전문업체를 통한 영향평가 수행 - 개발 반영 영역에 대한 반영 및 반경결과 확인(업무 전체) | AA25: 0 | AB25: 0 | AC25: 0 | AD25: 0
A26: RQ-기술협상-0490 | B26: 최신 보안지침 준수 | C26: □ 최신 보안지침 준수 ○ 조달청 최신(2021년) 보안기준을 적용하고 관련 지침 등을 준수하여야 함 | D26: 현행 | E26: 분석 | F26: 비기능 | G26: 수용 | I26: 중 | J26: 중 | K26: 2021-11-30 | M26: 사업관리/품질 | N26: 보안 | O26: 최신보안지침 준수 | Q26: 기술협상 | T26: 조황근 | U26: 이동헌 | V26: 1. 검토결과 - 최신 보안지침 준수 2. 구현방안/제약사항 - 2021년도 조달청 정보보안 세부지침 전문(조달청 훈령 제1971호) 적용 및 준수 | AA26: 0 | AB26: 0 | AC26: 0 | AD26: 0
A27: RQ-PER-001-0010 | B27: 성능을 고려한 개발방안 | C27: ㅇ사업대상 시스템의 성능을 고려한 개발 방안을 제시하여야 함 - 차세대 시스템의 전체 및 세부 아키텍처별 성능 관점에서 사용자 응답속도, 데이터 처리속도를 일정 수준 이상으로 보장하는 방안을 제안하고, 분석·설계 시 반영 - 대량의 데이터를 암·복호화 함에 있어서 성능지연에 대한 이슈를 AP·DB 튜닝 및 DB 구조변경 등으로 해결하여야 하며, 제안사는 이에 대한 객관적인 자료를 검사 전에 제시 | D27: 현행 | E27: 분석 | F27: 비기능 | G27: 수용 | I27: 상 | J27: 상 | K27: 2021-11-30 | M27: 사업관리/품질 | N27: 성능 | O27: 성능일반 | Q27: PER-001 | T27: 김야중 | U27: 김야중 | V27: 1. 검토결과 - 전체 및 세부 아키텍처별 성능관점 점검 후 반영(공통기술) - 암,복호화 성능지연에 대해서 AP, DB튜닝 및 구조변경으로 해결(공통기술, DB통합, 인프라) : 시스템(부하성능)테스트 수행 점검 및 개선사항 도출, 개선사항 해결 2. 구현방안/제약사항 [결과] 아키텍처정의서, 시스템(부하성능)테스트결과서 | Y27: 김훈희 | Z27: 이요한 | AA27: 0 | AB27: 0 | AC27: 0 | AD27: 0
A28: RQ-PER-001-0020 | B28: 안정적 운영지원 방안 | C28: 대상시스템에 대하여 안정적 운영지원 및 사용자 지원 방안을 제시하여야 함 | D28: 현행 | E28: 분석 | F28: 비기능 | G28: 수용 | I28: 상 | J28: 중 | K28: 2021-11-30 | M28: 사업관리/품질 | N28: 성능 | O28: 성능일반 | Q28: PER-001 | T28: 이동헌 | U28: 이동헌 | V28: 1. 검토결과 - 시스템에 대한 안정적 운영지원 및 사용자 지원 방안 제시 2. 구현방안/제약사항 - 안정화계획서를 통한 지원방안 제시(안정화계획서) | Y28: 김훈희 | Z28: 이요한 | AA28: 0 | AB28: 0 | AC28: 0 | AD28: 0
A29: RQ-PER-001-0030 | B29: 성능 문제 파악 후 조치 | C29: 시스템 개발 중 로그 또는 도구를 이용하여 시스템 성능상태를 모니터링 하도록 하여 성능 상 문제를 미리 파악하여 조치한 후 시스템을 오픈하여야 함 | D29: 현행 | E29: 분석 | F29: 비기능 | G29: 수용 | I29: 상 | J29: 중 | K29: 2021-11-30 | M29: 사업관리/품질 | N29: 성능 | O29: 성능일반 | Q29: PER-001 | T29: 김야중 | U29: 김야중 | V29: 1. 검토결과 - 개발 중 성능모니터링 방안 : 로그 또는 도구를 이용하여 성능상태 모니터링(문제 파악, 조치 수행) (공통기술과 확인 필요) * 개발중 성능 테스트를 주기적으로 수행 (QMS 연동, jMeter 환경 또는 프레임워크 로그관리를 통해서 적용 여부 확인 필요) 2. 구현방안/제약사항 [결과] PiMS 시스템의 QMS 수행 이력 확인 | Y29: 김훈희 | Z29: 이요한 | AA29: 0 | AB29: 0 | AC29: 0 | AD29: 0
A30: RQ-PER-002-0010 | B30: 온라인성 업무응답시간 | C30: ㅇ모든 질의는 사용자가 요청을 하는 시간으로부터 3초 내에 그 결과를 보여줘야 함 ㅇ이 요구사항은 임의의 선택 기준이 허용되는 대량의 데이터(데이터량 2GB 이상)에 대한 질의에는 적용되지 않음 | D30: 현행 | E30: 분석 | F30: 비기능 | G30: 수용 | I30: 중 | J30: 중 | K30: 2021-11-30 | M30: 사업관리/품질 | N30: 성능 | O30: 응답시간 | Q30: PER-002 | T30: 김야중 | U30: 김야중 | V30: 1. 검토결과 - (운영환경) 부하성능 테스트 수행을 통한 성능체크(대용량, 2GB 이상 질의 미적용) : 성능시험 전문가 투입 2. 구현방안/제약사항 [결과] 시스템(부하성능)테스트결과서 | Y30: 김훈희 | Z30: 이요한 | AA30: 0 | AB30: 0 | AC30: 0 | AD30: 0
A31: RQ-PER-003-0010 | B31: 온라인배치성 업무 응답시간 | C31: ㅇ온라인 배치성 업무에 대하여 3분 이내 그 결과를 보여주어야 함 ㅇ이 요구사항은 임의의 선택 기준이 허용되는 대량의 데이터에 대한 처리에는 적용되지 않음 | D31: 현행 | E31: 분석 | F31: 비기능 | G31: 수용 | I31: 중 | J31: 중 | K31: 2021-11-30 | M31: 사업관리/품질 | N31: 성능 | O31: 응답시간 | Q31: PER-003 | T31: 김야중 | U31: 김야중 | V31: 1. 검토결과 - (운영환경) 부하성능 테스트 수행을 통한 성능체크(온라인/배치성 업무)(대용량 데이터 처리 미적용) 2. 구현방안/제약사항 [결과] 시스템(부하성능)테스트결과서 | Y31: 김훈희 | Z31: 이요한 | AA31: 0 | AB31: 0 | AC31: 0 | AD31: 0
A32: RQ-PER-004-0010 | B32: 웹 페이지 디스플레이 시간 | C32: ㅇ정보시스템의 웹페이지는 사용자가 요청한 시간으로부터 3초 이내 완전히 디스플레이 되어야 함 ㅇ이 요구사항은 한 개 이상의 큰 이미지(이미지 50KB 이상) 및 동영상을 가지고 있는 페이지에 적용되지 않음 ㅇ이 요구사항은 시스템을 사용하는 사용자 숫자가 동시 사용자 용량의 90%를 초과하는 경우 적용하지 않음 - 대량 데이터 조회/출력/업·다운로드 시 작업을 시작하는 시점에 이에 따른 영향에 대해 사용자에게 팝업 메시지로 알림 | D32: 현행 | E32: 분석 | F32: 비기능 | G32: 수용 | I32: 중 | J32: 중 | K32: 2021-11-30 | M32: 사업관리/품질 | N32: 성능 | O32: 응답시간 | Q32: PER-004 | T32: 김야중 | U32: 김야중 | V32: 1. 검토결과 1) 웹페이지 요청한 시간으로부터 3초 이내 디스플레이(큰 이미지(50KB 이상), 동영상 포함 미적용, 동시 사용자 용량의 90% 초과 미 적용) 2) 대량 데이터 조회/출력/업·다운로드 시 작업을 시작하는 시점에 이에 따른 영향에 대해 사용자에게팝업 메시지로 알림(응용에서 대상 선정 메시지 처리) 2. 구현방안/제약사항 1) [결과] 시스템(부하성능)테스트결과서 2) [결과] 메시지 처리 적용 화면 | Y32: 김훈희 | Z32: 이요한 | AA32: 0 | AB32: 0 | AC32: 0 | AD32: 0
A33: RQ-PER-006-0010 | B33: 아키텍처 및 응용프로그램 검증 | C33: ㅇ 검증 대상 및 일정은 발주기관과 협의하여 시행 - 예) 입찰, 물품, 경리, 연계 등 ㅇ 아키텍처 검증환경 방안을 분석·설계단계에서 제시 ㅇ 성능테스트 수행이 가능한 전문 인력을 투입 ㅇ 동시접속자수 등을 고려하여 시스템의 성능이 최적화 될 수 있도록 시스템 성능 진단 및 향상을 위한 튜닝을 지속적으로 실시 ㅇ 개인정보보호 및 시스템 보안을 위한 암호화 적용 등 각종 보안 솔루션 적용에 따른 성능 저하에 대비한 방안을 수립하여 적용 ㅇ 피크타임 및 과부하에 따른 시스템 안정성 점검 | D33: 현행 | E33: 분석 | F33: 비기능 | G33: 수용 | I33: 상 | J33: 상 | K33: 2021-11-30 | M33: 사업관리/품질 | N33: 성능 | O33: 성능검증 | Q33: PER-006 | T33: 김야중 | U33: 김야중 | V33: 1. 검토결과 1) 아키텍처 검증환경 방안 분석,설계단계 제시 (공통기술) 2) 성능 전문인력 투입 (사업관리) 3) 성능테스트 후 튜닝 (전체업무) 2. 구현방안/제약사항 [결과] 시스템(부하성능)테스트결과서 | Y33: 김훈희 | Z33: 이요한 | AA33: 0 | AB33: 0 | AC33: 0 | AD33: 0
A34: RQ-FUN-공통-022-0010 | B34: 현행프로그램 개선방안 제시 | C34: ㅇ현행 프로그램에서 수행 중인 소스코드 등을 분석하여 현행 프로그램 오류, 구조적 결함, 설계 한계점을 분석하고 개선 방안 제시 - 제안사는 소스코드 현황 분석 결과, 장애·성능저하 요인 식별 결과 등을 기반으로 수행대상의 개선방안 및 개선전략을 제시하여야 함 - 사업범위 내 단위기능까지 수행 | D34: 현행 | E34: 분석 | F34: 비기능 | G34: 수용 | I34: 중 | J34: 중 | K34: 2021-11-30 | M34: 사업관리/품질 | N34: 소스코드분석 | O34: - | Q34: FUN-공통-022 | T34: 이동헌 | U34: 이동헌 | V34: 1. 검토결과 - 현행 프로그램 분석 후 개선방안 제시 2. 구현방안/제약사항 - 솔루션에 대한 선행검토 필요(사업관리) - 솔루션 선정 완료 후 AS-IS 소스에 대한 점검 수행 관리는 "공통기술" 관리 | Y34: 김훈희 | Z34: 이요한 | AA34: 0 | AB34: 0 | AC34: 0 | AD34: 0
A35: RQ-FUN-공통-022-0020 | B35: 소스코드 진단 | C35: ㅇ소스코드 정적분석 등 SW소스코드 진단을 통해 SW결함 또는 잠재결함을 검출하고 차세대 개발 시 미치는 영향도를 분석해야 함 - 발주기관의 요구사항을 반영하여 분석·설계 계획을 수립하고 분석을 수행해야 함 - 어플리케이션 및 다양한 SW의 개발언어(JAVA 등)에 대해 진단 해야 하며, 잠재 결함에 대한(또는 결함유형별) 개선코드 및 방향성을 제시해야함 - UTF8 등 인코딩 방식 변경에 따른 영향도 분석 및 적용방안 제시 | D35: 현행 | E35: 분석 | F35: 비기능 | G35: 수용 | I35: 중 | J35: 중 | K35: 2021-11-30 | M35: 사업관리/품질 | N35: 소스코드분석 | O35: - | Q35: FUN-공통-022 | T35: 이동헌 | U35: 이동헌 | V35: 1. 검토결과 - SW소스코드 진단을 통해 영향도 분석 2. 구현방안/제약사항 - 솔루션에 대한 선행검토 필요(사업관리) - 솔루션 선정 완료 후 AS-IS 소스에 대한 점검 수행 관리는 "공통기술" 관리 | Y35: 김훈희 | Z35: 이요한 | AA35: 0 | AB35: 0 | AC35: 0 | AD35: 0
A36: RQ-FUN-공통-022-0030 | B36: 소스코드 개선 방안 제시 | C36: ㅇ개선방안 작성 시, 발주기관이 개선방안을 쉽게 이해하고 이행할 수 있도록 상세하고 구체적으로 기술되어야 함 - 개선방안은 개선코드(예시), 통계데이터, 이미지 등을 활용하여 이해하기 쉽게 작성 - 개발언어의 버전 별 차이 분석(현행 및 적용 예정 버전) | D36: 현행 | E36: 분석 | F36: 비기능 | G36: 수용 | I36: 중 | J36: 중 | K36: 2021-11-30 | M36: 사업관리/품질 | N36: 소스코드분석 | O36: - | Q36: FUN-공통-022 | T36: 이동헌 | U36: 이동헌 | V36: 1. 검토결과 - 개선방안 작성 시 상세하고 구체적으로 기술 2. 구현방안/제약사항 - 솔루션에 대한 선행검토 필요(사업관리) - 솔루션 선정 완료 후 AS-IS 소스에 대한 점검 수행 관리는 "공통기술" 관리 | Y36: 김훈희 | Z36: 이요한 | AA36: 0 | AB36: 0 | AC36: 0 | AD36: 0
A37: RQ-기술협상-0170 | B37: 유지보수 시작 기준 | C37: □ 유지보수 시작 기준 ○ 제안한 HW, SW의 유지보수 시작일은 검사․검수를 완료한 시점을 기준으로 함 | D37: 현행 | E37: 분석 | F37: 비기능 | G37: 수용 | I37: 중 | J37: 중 | K37: 2021-11-30 | M37: 사업관리/품질 | N37: 시스템장비 | O37: 도입제품 | Q37: 기술협상 | T37: 이동헌 | U37: 이동헌 | V37: 1. 검토결과 - 유지보수 시작일은 검사, 검수를 완료한 시점 기준 2. 구현방안/제약사항 - 유지보수 계획수립 시 반영(유지보수계획서) | AA37: 0 | AB37: 0 | AC37: 0 | AD37: 0
A38: RQ-기술협상-0190 | B38: DBMS 협의 결정 | C38: □ DBMS 협의 결정 ○ 적용 DBMS의 선정은 전체 System Architecture를 고려하여 발주기관과 협의하여 결정함 ○ 도입되는 DBMS의 납품시기, 조건 등에 대해서는 발주기관의 불이익이 없어야 함 ○ 도입되는 DBMS는 나라장터 및 유관 시스템의 안정적 운영이 보장되어야 함 ○ 도입되는 DBMS에 따른 관리 도구, 개발도구, 모니터링 도구 등 기존 DBMS 지원 SW에 대한 안정성 확보가 담보되어야 함 | D38: 현행 | E38: 분석 | F38: 비기능 | G38: 수용 | I38: 중 | J38: 중 | K38: 2021-11-30 | M38: 사업관리/품질 | N38: 시스템장비 | O38: 도입 DBMS | Q38: 기술협상 | T38: 이동헌 | U38: 이동헌 | V38: 1. 검토결과 - 도입 DBMS 협의 결정 방안 2. 구현방안/제약사항 - 적용 DBMS의 선정은 전체 System Architecture를 고려하여 발주기관과 협의하여 결정 - 도입되는 DBMS의 납품시기, 조건 등에 대한 계획 수립 - 도입되는 DBMS는 나라장터 및 유관 시스템의 안정적 운영 보장 - 도입되는 DBMS에 따른 관리 도구, 개발도구, 모니터링 도구 등 기존 DBMS 지원 SW에 대한 안정성 확보 | AA38: 0 | AB38: 0 | AC38: 0 | AD38: 0
A39: RQ-기술협상-0360 | B39: SW 직접구매(분리발주) 세부 계획 수립 | C39: □ SW 직접구매(분리발주) 세부 계획 수립 ○ 분석․설계 내용을 감안한 SW 직접구매 세부계획을 수립하고 `22.2월까지 발주기관의 승인을 받아야 함 ○ SW 직접구매 세부 계획의 변경이 필요할 시 발주기관과 협의하여 결정하고 최종계획에 반영하여야 함 | D39: 현행 | E39: 분석 | F39: 비기능 | G39: 수용 | I39: 중 | J39: 중 | K39: 2021-11-30 | M39: 사업관리/품질 | N39: 시스템장비 | O39: 직접구매(분리발주) | Q39: 기술협상 | T39: 이동헌 | U39: 이동헌 | V39: 1. 검토결과 - SW 직접구매(분리발주) 세부계획 수립 방안 2. 구현방안/제약사항 - 분석 설계 내용을 감안한 SW 직접구매 세부계획 수립 - SW 직접구매 세부 계획의 변경 필요 시 조달청과 협의하여 결정 | AA39: 0 | AB39: 0 | AC39: 0 | AD39: 0
A40: RQ-FUN-공통-024-0020 | B40: 비대면 원격개발 | C40: ㅇ비대면 원격개발을 수행 할 경우 ‘국가정보보안 기본지침’ 제28조, 제52조 등 보안관리 가이드라인을 준수하여 수행하여야 함 | D40: 현행 | E40: 분석 | F40: 비기능 | G40: 수용 | I40: 중 | J40: 중 | K40: 2021-11-30 | M40: 사업관리/품질 | N40: 업무개발 | O40: - | Q40: FUN-공통-024 | T40: 조황근 | U40: 이동헌 | V40: 1. 검토결과 - 원격개발 수행 할 경우 보안관리 2. 구현방안/제약사항 - 코로나 등 원격개발 필요 상황 발생 시 추진단과 협의하여 국가정보보안 기본지침 제28조, 제52조 등 보안관리 가이드라인을 준수하여 수행 | Y40: 김훈희 | Z40: 이요한 | AA40: 0 | AB40: 0 | AC40: 0 | AD40: 0
...

Sheet Sheet1
N1: 구분 | O1: 서브시스템 | P1: 건수
C2: 업무구분 | D2: 건수 | G2: RQ-FUN-자체조달-100-0020 | H2: =VLOOKUP(G2, 상세현황!$A:$M, 2, FALSE) -> 공고자료 조회기간 확대 | N2: 사업관리 | O2: 사업관리/품질 | P2: =COUNTIF($H:$H, O2) -> 0
C3: 검사처리 | D3: =COUNTIF(상세현황!$N:$N, Sheet1!C3) -> 11 | G3: RQ-FUN-자체조달-100-0070 | H3: =VLOOKUP(G3, 상세현황!$A:$M, 2, FALSE) -> 견적공고 | N3: 공공조달 | O3: 운영관리(응용공통) | P3: =COUNTIF($H:$H, O3) -> 0
C4: 시정조치 | D4: =COUNTIF(상세현황!$N:$N, Sheet1!C4) -> 10 | G4: RQ-FUN-자체조달-100-0110 | H4: =VLOOKUP(G4, 상세현황!$A:$M, 2, FALSE) -> 구매요청(구매요청 문서 생성) | O4: 조달요청 | P4: =COUNTIF($H:$H, O4) -> 0
C5: 업체생산능력확인 | D5: =COUNTIF(상세현황!$N:$N, Sheet1!C5) -> 6 | G5: RQ-FUN-자체조달-100-0130 | H5: =VLOOKUP(G5, 상세현황!$A:$M, 2, FALSE) -> 계약방법결정(품목별 계약방법 생성) | O5: 공고 | P5: =COUNTIF($H:$H, O5) -> 0
C6: 품질보증결과 | D6: =COUNTIF(상세현황!$N:$N, Sheet1!C6) -> 16 | G6: RQ-FUN-자체조달-100-0160 | H6: =VLOOKUP(G6, 상세현황!$A:$M, 2, FALSE) -> 업체추천 | O6: 가격 | P6: =COUNTIF($H:$H, O6) -> 0
C7: 품질보증계획 | D7: =COUNTIF(상세현황!$N:$N, Sheet1!C7) -> 5 | G7: RQ-FUN-자체조달-100-0200 | H7: =VLOOKUP(G7, 상세현황!$A:$M, 2, FALSE) -> 폐광지역 제한경쟁 및 수의계약 | O7: 입찰 | P7: =COUNTIF($H:$H, O7) -> 0
C8: 품질보증수행 | D8: =COUNTIF(상세현황!$N:$N, Sheet1!C8) -> 2 | G8: RQ-FUN-자체조달-100-0230 | H8: =VLOOKUP(G8, 상세현황!$A:$M, 2, FALSE) -> 발전소 주변지역 제한경쟁 기능 | O8: 계약체결 | P8: =COUNTIF($H:$H, O8) -> 0
C9: 품질보증준비 | D9: =COUNTIF(상세현황!$N:$N, Sheet1!C9) -> 12 | G9: RQ-FUN-자체조달-100-0231 | H9: =VLOOKUP(G9, 상세현황!$A:$M, 2, FALSE) -> 발전소 주변지역 제한경쟁 기능(현장실사) | O9: 계약관리 | P9: =COUNTIF($H:$H, O9) -> 0
C10: 하자관리 | D10: =COUNTIF(상세현황!$N:$N, Sheet1!C10) -> 21 | G10: RQ-FUN-자체조달-100-0250 | H10: =VLOOKUP(G10, 상세현황!$A:$M, 2, FALSE) -> 원자력 품질자재구매 유자격자 명부 관리 기능 | N10: 상품조달 | O10: 쇼핑몰 | P10: =COUNTIF($H:$H, O10) -> 0
G11: RQ-FUN-자체조달-100-0320 | H11: =VLOOKUP(G11, 상세현황!$A:$M, 2, FALSE) -> 발주 프로세스 자동화 | N11: 조달지원 | O11: 경리 | P11: =COUNTIF($H:$H, O11) -> 0
G12: RQ-FUN-자체조달-100-0321 | H12: =VLOOKUP(G12, 상세현황!$A:$M, 2, FALSE) -> 발주프로세스 자동화 | O12: 지원공통 | P12: =COUNTIF($H:$H, O12) -> 0
G13: RQ-FUN-자체조달-100-0370 | H13: =VLOOKUP(G13, 상세현황!$A:$M, 2, FALSE) -> 수수료율 투찰
G14: RQ-FUN-자체조달-100-0440 | H14: =VLOOKUP(G14, 상세현황!$A:$M, 2, FALSE) -> 예외적 계약진행 종료
G15: RQ-FUN-자체조달-100-0460 | H15: =VLOOKUP(G15, 상세현황!$A:$M, 2, FALSE) -> 예비가격(복수예비가격)
G16: RQ-FUN-자체조달-100-0470 | H16: =VLOOKUP(G16, 상세현황!$A:$M, 2, FALSE) -> 협상회의록
G17: RQ-FUN-자체조달-100-0520 | H17: =VLOOKUP(G17, 상세현황!$A:$M, 2, FALSE) -> 수의시담 복수예비가격
G18: RQ-FUN-자체조달-100-0720 | H18: =VLOOKUP(G18, 상세현황!$A:$M, 2, FALSE) -> 식자재 유자격자 제도
G19: RQ-FUN-자체조달-100-0722 | H19: =VLOOKUP(G19, 상세현황!$A:$M, 2, FALSE) -> 식자재 유자격자 제도 및 식자재 입찰계약
G20: RQ-FUN-자체조달-100-0760 | H20: =VLOOKUP(G20, 상세현황!$A:$M, 2, FALSE) -> 계약체결_첨부파일,물품 직접등록
G21: RQ-FUN-자체조달-100-0770 | H21: =VLOOKUP(G21, 상세현황!$A:$M, 2, FALSE) -> 계약체결_전자인증
G22: RQ-FUN-자체조달-100-0780 | H22: =VLOOKUP(G22, 상세현황!$A:$M, 2, FALSE) -> 계약관리 현황
G23: RQ-FUN-조달지원-066-0060 | H23: =VLOOKUP(G23, 상세현황!$A:$M, 2, FALSE) -> 한국전자통신연구원 나라장터 이용수수료 고지방식 개선
G24: RQ-FUN-자체조달-100-0850 | H24: =VLOOKUP(G24, 상세현황!$A:$M, 2, FALSE) -> 제안서 접수 및 송부_입찰서류접수
... G28: RQ-FUN-자체조달-100-1000 | H28: =VLOOKUP(G28, 상세현황!$A:$M, 2, FALSE) -> 다국어지원(영어)
